<?xml version="1.0" encoding="utf-8"?>
<!-- This URDF was automatically created by SolidWorks to URDF Exporter! Originally created by Stephen Brawner (brawner@gmail.com) 
     Commit Version: 1.6.0-4-g7f85cfe  Build Version: 1.6.7995.38578
     For more information, please see http://wiki.ros.org/sw_urdf_exporter -->
<robot xmlns:xacro="http://www.ros.org/wiki/xacro"
  name="Esamble_Sencillo_gripper">

  <!-- Link "mundo" para anclar el robot -->
  <link name="world" />
  
  <joint name="world_to_base_joint" type="fixed">
    <parent link="world" />
    <child link="base_link" />
    <origin xyz="0 0 0" rpy="0 0 0" />
  </joint>
  

  <link
    name="base_link">
    <inertial>
      <origin
        xyz="-0.0050268 -0.078183 -0.0225"
        rpy="0 0 0" />
      <mass
        value="1.5106" />
      <inertia
        ixx="0.0093016"
        ixy="-0.00083013"
        ixz="-7.7076E-20"
        iyy="0.0025817"
        iyz="-1.5891E-19"
        izz="0.011373" />
    </inertial>
    <visual>
      <origin
        xyz="0 -0.0425 0"
        rpy="1.57 0 0" />
      <geometry>
        <mesh
          filename="package://scara_description/meshes/base_link.STL" />
      </geometry>
      <material
        name="">
        <color
          rgba="0.5 1.0 0.8 1.0" /> 
      </material>
    </visual>
    <collision>
      <origin
        xyz="0 -0.0425 0"
        rpy="1.57 0 0" />
      <geometry>
        <mesh
          filename="package://scara_description/meshes/base_link.STL" />
      </geometry>
    </collision>
  </link>


  <link
    name="Revolute_1_Link">
    <inertial>
      <origin
        xyz="0.00013035 -6.9389E-18 0.14006"
        rpy="0 0 0" />
      <mass
        value="1.4899" />
      <inertia
        ixx="0.035352"
        ixy="-3.1241E-21"
        ixz="3.3345E-05"
        iyy="0.035365"
        iyz="1.3213E-18"
        izz="0.0016385" />
    </inertial>
    <visual>
      <origin
        xyz="0 -0.0425 -0.0525"
        rpy="1.57 0 0" />
      <geometry>
        <mesh
          filename="package://scara_description/meshes/Revolute_1_Link.STL" />
      </geometry>
      <material
        name="">
        <color
          rgba="0.8 0.8 0.8 1.0" />
      </material>
    </visual>
    <collision>
      <origin
        xyz="0 -0.0425 -0.0525"
        rpy="1.57 0 0" />
      <geometry>
        <mesh
          filename="package://scara_description/meshes/Revolute_1_Link.STL" />
      </geometry>
    </collision>
  </link>


  <joint
    name="Revolute_1_Jint"
    type="revolute">
    <origin
      xyz="0 0 0.0525"
      rpy="0 0 0" />
    <parent
      link="base_link" />
    <child
      link="Revolute_1_Link" />
    <axis
      xyz="0 0 1" />
  <limit lower="-3.1415" upper="3.1415" effort="10" velocity="1.0" />
  </joint>


  <link
    name="Prismatic_1_link">
    <inertial>
      <origin
        xyz="0.094766 0 0.0225"
        rpy="0 0 0" />
      <mass
        value="1.2694" />
      <inertia
        ixx="0.0013484"
        ixy="5.6661E-19"
        ixz="5.1896E-20"
        iyy="0.009623"
        iyz="-2.4505E-22"
        izz="0.010543" />
    </inertial>
    <visual>
      <origin
        xyz="0 -0.0425 -0.3"
        rpy="1.57 0 0" />
      <geometry>
        <mesh
          filename="package://scara_description/meshes/Prismatic_1_link.STL" />
      </geometry>
      <material
        name="">
        <color
          rgba="1.0 1.0 0.8 1.0" />
      </material>
    </visual>
    <collision>
      <origin
        xyz="0 -0.0425 -0.3"
        rpy="1.57 0 0" />
      <geometry>
        <mesh
          filename="package://scara_description/meshes/Prismatic_1_link.STL" />
      </geometry>
    </collision>
  </link>
  <joint
    name="Prismatic_1_Joint"
    type="prismatic">
    <origin
      xyz="0 0 0.0525"
      rpy="0 0 0" />
    <parent
      link="Revolute_1_Link" />
    <child
      link="Prismatic_1_link" />
    <axis
      xyz="0 0 1" />
    <limit
      lower="0"
      upper="0.254"
      effort="0"
      velocity="0" />
  </joint>
  <link
    name="Revolute_2_Link">
    <inertial>
      <origin
        xyz="0.061686 -6.9389E-18 -0.015864"
        rpy="0 0 0" />
      <mass
        value="0.61164" />
      <inertia
        ixx="0.00044425"
        ixy="2.8532E-20"
        ixz="0.00013287"
        iyy="0.0022992"
        iyz="-1.7404E-20"
        izz="0.0024904" />
    </inertial>
    <visual>
      <origin
        xyz="-0.228 -0.0425 -0.281"
        rpy="1.57 0 0" />
      <geometry>
        <mesh
          filename="package://scara_description/meshes/Revolute_2_Link.STL" />
      </geometry>
      <material
        name="">
        <color
          rgba="1.0 0.6 0.5 1.0" />
      </material>
    </visual>
    <collision>
      <origin
        xyz="-0.228 -0.0425 -0.281"
        rpy="1.57 0 0" />
      <geometry>
        <mesh
          filename="package://scara_description/meshes/Revolute_2_Link.STL" />
      </geometry>
    </collision>
  </link>
  <joint
    name="Revolute_2_Joint"
    type="revolute">
    <origin
      xyz="0.228 0 -0.019"
      rpy="0 0 0" />
    <parent
      link="Prismatic_1_link" />
    <child
      link="Revolute_2_Link" />
    <axis
      xyz="0 0 1" />
    <limit lower="-3.1415" upper="3.1415" effort="10" velocity="1.0" />
  </joint>
  <link
    name="Revolute_3_Link">
    <inertial>
      <origin
        xyz="0.00011013 0 0.0012399"
        rpy="0 0 0" />
      <mass
        value="0.18414" />
      <inertia
        ixx="0.00022791"
        ixy="-9.8815E-22"
        ixz="7.5358E-09"
        iyy="0.00023992"
        iyz="-5.115E-21"
        izz="7.1114E-05" />
    </inertial>
    <visual>
      <origin
        xyz="-0.363 -0.0425 -0.224"
        rpy="1.57 0 0" />
      <geometry>
        <mesh
          filename="package://scara_description/meshes/Revolute_3_Link.STL" />
      </geometry>
      <material
        name="">
        <color
          rgba="1.0 0.5 0.0 1.0" />
      </material>
    </visual>
    <collision>
      <origin
        xyz="-0.363 -0.0425 -0.224"
        rpy="1.57 0 0" />
      <geometry>
        <mesh
          filename="package://scara_description/meshes/Revolute_3_Link.STL" />
      </geometry>
    </collision>
  </link>

  <joint
    name="Revolute_3_Joint"
    type="revolute">
    <origin
      xyz="0.1365 0 -0.057"
      rpy="0 0 0" />
    <parent
      link="Revolute_2_Link" />
    <child
      link="Revolute_3_Link" />
    <axis
      xyz="0 0 -1" />
    <limit lower="-3.1415" upper="3.1415" effort="10" velocity="1.0" />
  </joint>

  <link
    name="Griper_Left_Link">
    <inertial>
      <origin
        xyz="0.033773 1.3878E-17 -0.014211"
        rpy="0 0 0" />
      <mass
        value="0.047823" />
      <inertia
        ixx="4.7679E-06"
        ixy="-1.7177E-20"
        ixz="2.8888E-06"
        iyy="4.5792E-05"
        iyz="9.5566E-22"
        izz="4.7001E-05" />
    </inertial>
    <visual>
      <origin
        xyz="-0.1315 -0.0425 0.326"
        rpy="1.57 1.57 0" />
      <geometry>
        <mesh
          filename="package://scara_description/meshes/Griper_Left_Link.STL" />
      </geometry>
      <material
        name="">
        <color
          rgba="0.8 0.7 1.0 1.0" />
      </material>
    </visual>
    <collision>
      <origin
        xyz="-0.1315 -0.0425 0.326"
        rpy="1.57 1.57 0" />
      <geometry>
        <mesh
          filename="package://scara_description/meshes/Griper_Left_Link.STL" />
      </geometry>
    </collision>
  </link>


  <joint
    name="Gripper_Left_Joint"
    type="prismatic">
    <origin
      xyz="-0.03775 0 -0.0925"
      rpy="-1.5708 -1.5708 1.5708" />
    <parent
      link="Revolute_3_Link" />
    <child
      link="Griper_Left_Link" />
    <axis
      xyz="0 0 -1" />
    <limit
      lower="0"
      upper="0.033"
      effort="0"
      velocity="0" />
  </joint>


  <link
    name="Gripper_Right_Link">
    <inertial>
      <origin
        xyz="0 0.033773 -0.014211"
        rpy="0 0 0" />
      <mass
        value="0.047823" />
      <inertia
        ixx="4.5792E-05"
        ixy="1.3317E-20"
        ixz="-1.1452E-21"
        iyy="4.7679E-06"
        iyz="2.8888E-06"
        izz="4.7001E-05" />
    </inertial>
    <visual>
      <origin
        xyz="0.0425 -0.131 0.40"
        rpy="0 1.57 0" />
      <geometry>
        <mesh
          filename="package://scara_description/meshes/Gripper_Right_Link.STL" />
      </geometry>
      <material
        name="">
        <color
          rgba="0.8 0.7 1.0 1.0" />
      </material>
    </visual>
    <collision>
      <origin
        xyz="0.0425 -0.131 0.40"
        rpy="0 1.57 0" />
      <geometry>
        <mesh
          filename="package://scara_description/meshes/Gripper_Right_Link.STL" />
      </geometry>
    </collision>
  </link>
  <joint
    name="Gripper_Right_Joint"
    type="prismatic">
    <origin
      xyz="0.03775 0 -0.093"
      rpy="1.5708 0 -1.5708" />
    <parent
      link="Revolute_3_Link" />
    <child
      link="Gripper_Right_Link" />
    <axis
      xyz="0 0 1" />
    <limit
      lower="0"
      upper="0.033"
      effort="0"
      velocity="0" />
  </joint>

  <!-- ========= INICIO DE LA SECCIÓN CORREGIDA ========= -->
  <!-- Importar la configuración de ros2_control desde el paquete de MoveIt -->
  <xacro:include filename="$(find scara_moveit_config)/config/Esamble_Sencillo_gripper.ros2_control.xacro" />

  <!-- Instanciar la macro definida en el archivo importado -->
  <xacro:Esamble_Sencillo_gripper_ros2_control name="GazeboSim" initial_positions_file="$(find scara_moveit_config)/config/initial_positions.yaml"/>
  <!-- ========= FIN DE LA SECCIÓN CORREGIDA ========= -->

</robot>
